Traceback (most recent call last):
  File "D:\INACAP\2024 Ingenieria\8vo semestre\Machine Learning\Unidad 4\ML_Eva4\ML_Eva4\Lib\site-packages\pandas\core\indexes\base.py", line 3812, in get_loc
    return self._engine.get_loc(casted_key)
           ^^^^^^^^^^^^^^^^^^^^^^^^^^^^^^^^
  File "pandas/_libs/index.pyx", line 167, in pandas._libs.index.IndexEngine.get_loc
  File "pandas/_libs/index.pyx", line 196, in pandas._libs.index.IndexEngine.get_loc
  File "pandas/_libs/hashtable_class_helper.pxi", line 7088, in pandas._libs.hashtable.PyObjectHashTable.get_item
  File "pandas/_libs/hashtable_class_helper.pxi", line 7096, in pandas._libs.hashtable.PyObjectHashTable.get_item
KeyError: 'text'

The above exception was the direct cause of the following exception:

Traceback (most recent call last):
  File "D:\INACAP\2024 Ingenieria\8vo semestre\Machine Learning\Unidad 4\ML_Eva4\scripts\train.py", line 91, in <module>
    main(args.config, args.model_path, args.metrics_path)
  File "D:\INACAP\2024 Ingenieria\8vo semestre\Machine Learning\Unidad 4\ML_Eva4\scripts\train.py", line 51, in main
    texts, labels = load_data()
                    ^^^^^^^^^^^
  File "D:\INACAP\2024 Ingenieria\8vo semestre\Machine Learning\Unidad 4\ML_Eva4\scripts\train.py", line 23, in load_data
    texts = df['text'].values
            ~~^^^^^^^^
  File "D:\INACAP\2024 Ingenieria\8vo semestre\Machine Learning\Unidad 4\ML_Eva4\ML_Eva4\Lib\site-packages\pandas\core\frame.py", line 4107, in __getitem__
    indexer = self.columns.get_loc(key)
              ^^^^^^^^^^^^^^^^^^^^^^^^^
  File "D:\INACAP\2024 Ingenieria\8vo semestre\Machine Learning\Unidad 4\ML_Eva4\ML_Eva4\Lib\site-packages\pandas\core\indexes\base.py", line 3819, in get_loc
    raise KeyError(key) from err
KeyError: 'text'
