Epoch 1/5
Traceback (most recent call last):
  File "D:\INACAP\2024 Ingenieria\8vo semestre\Machine Learning\Unidad 4\ML_Eva4\scripts\train.py", line 103, in <module>
    main(args.config, args.model_path, args.metrics_path)
  File "D:\INACAP\2024 Ingenieria\8vo semestre\Machine Learning\Unidad 4\ML_Eva4\scripts\train.py", line 65, in main
    history = model.fit(
              ^^^^^^^^^^
  File "D:\INACAP\2024 Ingenieria\8vo semestre\Machine Learning\Unidad 4\ML_Eva4\ML_Eva4\Lib\site-packages\keras\src\utils\traceback_utils.py", line 122, in error_handler
    raise e.with_traceback(filtered_tb) from None
  File "D:\INACAP\2024 Ingenieria\8vo semestre\Machine Learning\Unidad 4\ML_Eva4\ML_Eva4\Lib\site-packages\tensorflow\python\eager\execute.py", line 59, in quick_execute
    except TypeError as e:
tensorflow.python.framework.errors_impl.InvalidArgumentError: Graph execution error:

Detected at node sequential_1/embedding_1/GatherV2 defined at (most recent call last):
  File "D:\INACAP\2024 Ingenieria\8vo semestre\Machine Learning\Unidad 4\ML_Eva4\scripts\train.py", line 103, in <module>

  File "D:\INACAP\2024 Ingenieria\8vo semestre\Machine Learning\Unidad 4\ML_Eva4\scripts\train.py", line 65, in main

  File "D:\INACAP\2024 Ingenieria\8vo semestre\Machine Learning\Unidad 4\ML_Eva4\ML_Eva4\Lib\site-packages\keras\src\utils\traceback_utils.py", line 117, in error_handler

  File "D:\INACAP\2024 Ingenieria\8vo semestre\Machine Learning\Unidad 4\ML_Eva4\ML_Eva4\Lib\site-packages\keras\src\backend\tensorflow\trainer.py", line 377, in fit

  File "D:\INACAP\2024 Ingenieria\8vo semestre\Machine Learning\Unidad 4\ML_Eva4\ML_Eva4\Lib\site-packages\keras\src\backend\tensorflow\trainer.py", line 220, in function

  File "D:\INACAP\2024 Ingenieria\8vo semestre\Machine Learning\Unidad 4\ML_Eva4\ML_Eva4\Lib\site-packages\keras\src\backend\tensorflow\trainer.py", line 133, in multi_step_on_iterator

  File "D:\INACAP\2024 Ingenieria\8vo semestre\Machine Learning\Unidad 4\ML_Eva4\ML_Eva4\Lib\site-packages\keras\src\backend\tensorflow\trainer.py", line 114, in one_step_on_data

  File "D:\INACAP\2024 Ingenieria\8vo semestre\Machine Learning\Unidad 4\ML_Eva4\ML_Eva4\Lib\site-packages\keras\src\backend\tensorflow\trainer.py", line 58, in train_step

  File "D:\INACAP\2024 Ingenieria\8vo semestre\Machine Learning\Unidad 4\ML_Eva4\ML_Eva4\Lib\site-packages\keras\src\utils\traceback_utils.py", line 117, in error_handler

  File "D:\INACAP\2024 Ingenieria\8vo semestre\Machine Learning\Unidad 4\ML_Eva4\ML_Eva4\Lib\site-packages\keras\src\layers\layer.py", line 936, in __call__

  File "D:\INACAP\2024 Ingenieria\8vo semestre\Machine Learning\Unidad 4\ML_Eva4\ML_Eva4\Lib\site-packages\keras\src\utils\traceback_utils.py", line 117, in error_handler

  File "D:\INACAP\2024 Ingenieria\8vo semestre\Machine Learning\Unidad 4\ML_Eva4\ML_Eva4\Lib\site-packages\keras\src\ops\operation.py", line 58, in __call__

  File "D:\INACAP\2024 Ingenieria\8vo semestre\Machine Learning\Unidad 4\ML_Eva4\ML_Eva4\Lib\site-packages\keras\src\utils\traceback_utils.py", line 156, in error_handler

  File "D:\INACAP\2024 Ingenieria\8vo semestre\Machine Learning\Unidad 4\ML_Eva4\ML_Eva4\Lib\site-packages\keras\src\models\sequential.py", line 220, in call

  File "D:\INACAP\2024 Ingenieria\8vo semestre\Machine Learning\Unidad 4\ML_Eva4\ML_Eva4\Lib\site-packages\keras\src\models\functional.py", line 183, in call

  File "D:\INACAP\2024 Ingenieria\8vo semestre\Machine Learning\Unidad 4\ML_Eva4\ML_Eva4\Lib\site-packages\keras\src\ops\function.py", line 177, in _run_through_graph

  File "D:\INACAP\2024 Ingenieria\8vo semestre\Machine Learning\Unidad 4\ML_Eva4\ML_Eva4\Lib\site-packages\keras\src\models\functional.py", line 648, in call

  File "D:\INACAP\2024 Ingenieria\8vo semestre\Machine Learning\Unidad 4\ML_Eva4\ML_Eva4\Lib\site-packages\keras\src\utils\traceback_utils.py", line 117, in error_handler

  File "D:\INACAP\2024 Ingenieria\8vo semestre\Machine Learning\Unidad 4\ML_Eva4\ML_Eva4\Lib\site-packages\keras\src\layers\layer.py", line 936, in __call__

  File "D:\INACAP\2024 Ingenieria\8vo semestre\Machine Learning\Unidad 4\ML_Eva4\ML_Eva4\Lib\site-packages\keras\src\utils\traceback_utils.py", line 117, in error_handler

  File "D:\INACAP\2024 Ingenieria\8vo semestre\Machine Learning\Unidad 4\ML_Eva4\ML_Eva4\Lib\site-packages\keras\src\ops\operation.py", line 58, in __call__

  File "D:\INACAP\2024 Ingenieria\8vo semestre\Machine Learning\Unidad 4\ML_Eva4\ML_Eva4\Lib\site-packages\keras\src\utils\traceback_utils.py", line 156, in error_handler

  File "D:\INACAP\2024 Ingenieria\8vo semestre\Machine Learning\Unidad 4\ML_Eva4\ML_Eva4\Lib\site-packages\keras\src\layers\core\embedding.py", line 150, in call

  File "D:\INACAP\2024 Ingenieria\8vo semestre\Machine Learning\Unidad 4\ML_Eva4\ML_Eva4\Lib\site-packages\keras\src\ops\numpy.py", line 5581, in take

  File "D:\INACAP\2024 Ingenieria\8vo semestre\Machine Learning\Unidad 4\ML_Eva4\ML_Eva4\Lib\site-packages\keras\src\backend\tensorflow\numpy.py", line 2274, in take

indices[25,6] = 7170 is not in [0, 5000)
	 [[{{node sequential_1/embedding_1/GatherV2}}]] [Op:__inference_multi_step_on_iterator_4785]
